Workbook

Sheet Read Me
A1: Project Odyssey - MVP Backlog
A2: Working tracker for developers. The source of truth is Project Odyssey.docx v2.0, chapter 12; this workbook is generated from the same data. Updated 2026-10-01: M7-M9 added (D-34); statuses of built stories set to Done.
A4: How to use
A5: 1. Work milestone by milestone (Timeline sheet). Never start a story whose dependencies are not Decided (Dependencies sheet).
A6: 2. Update only the yellow cells: Status on the User Stories sheet, the project start date and week estimates on the Timeline sheet.
A7: 3. Status values: To do, In progress, Blocked, Done. A story is Done only when it meets the Definition of Done.
A8: 4. Epic progress and the timeline recalculate automatically.
A9: 5. Example: set US-001 to 'In progress' when you start installing tools, and to 'Done' when a clean checkout builds and debugs.
A11: Story sizes (used by formulas)
A12: Size | B12: Weeks (low) | C12: Weeks (high) | D12: Meaning (part-time, beginner pace, learning included)
A13: S | B13: 0.5 | C13: 1 | D13: Up to about a week
A14: M | B14: 1 | C14: 2 | D14: One to two weeks
A15: L | B15: 2 | C15: 4 | D15: Two to four weeks; split if it grows

Sheet MVP Definition
A1: MVP definition
A2: Product Owner + Solution Architect, 2026-09-29. Status 'Proposed' = awaiting your decision.
A4: Hypothesis
A5: We believe that living one Neanderthal's life on a procedurally generated region, from the Growing Period to leading a clan, will produce emergent stories that make players want to keep playing. We will know when at least 5 of 8 outside playtesters play 30+ minutes unprompted and at least 3 can retell a story that emerged from the simulation. At the same time, the MVP proves the architecture: 60 FPS, deterministic, headless-testable, on Windows x64.
A7: Scope (in)
A8: ID | B8: Area | C8: MVP scope | D8: Status | E8: Traces to
A9: MVP-01 | B9: Platform | C9: Windows x64 only. Android and iOS are out of the MVP (architecture keeps them possible). | D9: Proposed | E9: PLT-01, PLT-02
A10: MVP-02 | B10: Age | C10: Age 1 only: Late Paleolithic, Age of Embers (c. 40,000 BCE). | D10: Proposed | E10: ENV-01, ENV-09
A11: MVP-03 | B11: World | C11: One procedurally generated region (256 x 256 tiles, 64 x 64-tile chunks), not a whole planet. Bounded edges; planet projection deferred. | D11: Proposed | E11: ENV-03, ARC-06, OPEN-02
A12: MVP-04 | B12: Game Mode | C12: One Hero per Age only (smallest scope, recommended first mode). | D12: Proposed | E12: CHR-02
A13: MVP-05 | B13: Modifiers | C13: Only the baseline modifier Random per World, plus Growing Period presets (Off / Compressed / Full) and the Comfort dial (Cozy / Balanced / Harsh). | D13: Proposed | E13: CHR-03, CHR-06, ENV-07
A14: MVP-06 | B14: Character | C14: Full Growing Period (ages 12-26) with Focus slots, Crossroads events, imprint curve and the Mantle moment; aging and death. | D14: Proposed | E14: CHR-05, CHR-06
A15: MVP-07 | B15: Professions | C15: Five Age 1 professions, data-driven: Hunter, Gatherer, Flint-knapper, Fire-keeper, Shaman-healer. | D15: Proposed | E15: CHR-07, Flag 5
A16: MVP-08 | B16: Pillars | C16: Two pillars playable at region scale: Trade (barter and debts) and Religion (sacred fire and followers). The other four are shown as locked 'later Ages'. | D16: Proposed | E16: PIL-02, PIL-04, ENV-10
A17: MVP-09 | B17: Victory | C17: Win: your clan leads the region (Dominion 60% in Trade or Religion, or 50% combined). Lose: your hero dies before the Mantle moment, or your clan disbands. | D17: Proposed | E17: ENV-05, ENV-10
A18: MVP-10 | B18: Simulation | C18: One player clan (about 20 people) and two rival AI clans; LOD tiers Active and Nearby only. | D18: Proposed | E18: ARC-05, ADR-013
A19: MVP-11 | B19: Presentation | C19: Layered 32 x 48 sprites with 3 outfits per body; programmer or placeholder art allowed; minimal sound effects. | D19: Proposed | E19: ENV-11, ENV-12, OPEN-11, OPEN-12
... A22: MVP-14 | B22: Interactions | C22: Data-driven world interactions shared by the player, NPCs and animals; talking to NPCs (written + generated); interactions and dialogue editable offline (JSON, .dlg) and in the Editor's graph view. Built before kill gate 2 (D-34, 2026-10-01). | D22: Decided | E22: INT-01..INT-06, SDC-03..SDC-06, ADR-019
A24: Success and kill criteria (decided before building)
A25: Metric | B25: Target | C25: How measured | D25: Gate
A26: Voluntary play time | B26: 5 of 8 playtesters play 30+ minutes without being asked to continue | C26: Observation + local session log (US-092) | D26: M6
A27: Emergent story | B27: 3 of 8 can retell a story that came from the simulation, not from a script | C27: Post-play interview | D27: M6
A28: Chronicle interest (early) | B28: 2 of 3 readers find a story in the console chronicle | C28: Show printed chronicle (M2: 3 readers, failed 2026-09-30; M2b retry: the owner reads and judges) | D28: M2, retried at M2b
A29: Frame rate | B29: 60 FPS with 500 simulated agents in the region on the minimum PC (OPEN-19) | C29: FPS overlay (US-082) | D29: M5
A30: Determinism | B30: Same seed + inputs give the same world hash after 10,000 ticks | C30: Automated test in CI | D30: M2 onwards
A31: Stability | B31: No crash in a 2-hour play session or a 100-year soak test | C31: Soak test + crash log | D31: M5, M6
A32: Kill / pivot rule | B32: If M2 or M6 fails: stop adding content; redesign the simulation or the loop first | C32: Owner decision, recorded | D32: M2, M6

Sheet Timeline
A1: Timeline: milestones and Gantt (likely plan)
A2: Estimates are bottom-up from story sizes, part-time, beginner pace. Yellow cells are editable. Bars show the likely plan.
A4: Project start (Monday) | B4: 46300
A6: ID | B6: Milestone | C6: Learning stages | D6: Weeks optimistic | E6: Weeks pessimistic | F6: Weeks likely | G6: Start week | H6: End week (likely) | I6: Start date | J6: End date (likely) | K6: End date (optimistic) | L6: End date (pessimistic) | M6: Must story weeks (low-high) | N6: Exit criteria (demonstrable) | P6: 1 | Q6: 2 | R6: 3 | S6: 4 | T6: 5 | U6: 6 | V6: 7 | W6: 8 | X6: 9 | Y6: 10 | Z6: 11 | AA6: 12 | AB6: 13 | AC6: 14 | AD6: 15 | AE6: 16 | AF6: 17 | AG6: 18 | AH6: 19 | AI6: 20 | AJ6: 21 | AK6: 22 | AL6: 23 | AM6: 24 | AN6: 25 | AO6: 26 | AP6: 27 | AQ6: 28 | AR6: 29 | AS6: 30 | AT6: 31 | AU6: 32 | AV6: 33 | AW6: 34 | AX6: 35 | AY6: 36 | AZ6: 37 | BA6: 38 | BB6: 39 | BC6: 40 | BD6: 41 | BE6: 42 | BF6: 43 | BG6: 44 | BH6: 45 | BI6: 46 | BJ6: 47 | BK6: 48 | BL6: 49 | BM6: 50 | BN6: 51 | BO6: 52 | BP6: 53 | BQ6: 54 | BR6: 55 | BS6: 56 | BT6: 57 | BU6: 58 | BV6: 59 | BW6: 60 | BX6: 61 | BY6: 62 | BZ6: 63 | CA6: 64 | CB6: 65 | CC6: 66 | CD6: 67 | CE6: 68 | CF6: 69 | CG6: 70 | CH6: 71 | CI6: 72 | CJ6: 73 | CK6: 74 | CL6: 75 | CM6: 76 | CN6: 77 | CO6: 78 | CP6: 79 | CQ6: 80 | CR6: 81 | CS6: 82 | CT6: 83 | CU6: 84 | CV6: 85 | CW6: 86 | CX6: 87 | CY6: 88 | CZ6: 89 | DA6: 90 | DB6: 91 | DC6: 92 | DD6: 93 | DE6: 94 | DF6: 95 | DG6: 96 | DH6: 97 | DI6: 98 | DJ6: 99 | DK6: 100 | DL6: 101 | DM6: 102 | DN6: 103 | DO6: 104 | DP6: 105 | DQ6: 106 | DR6: 107 | DS6: 108 | DT6: 109 | DU6: 110 | DV6: 111 | DW6: 112 | DX6: 113 | DY6: 114 | DZ6: 115 | EA6: 116 | EB6: 117 | EC6: 118 | ED6: 119 | EE6: 120 | EF6: 121 | EG6: 122 | EH6: 123 | EI6: 124 | EJ6: 125 | EK6: 126 | EL6: 127 | EM6: 128 | EN6: 129 | EO6: 130 | EP6: 131 | EQ6: 132 | ER6: 133 | ES6: 134 | ET6: 135 | EU6: 136 | EV6: 137 | EW6: 138 | EX6: 139 | EY6: 140
A7: M0 | B7: Tooling ready | C7: 0 | D7: 2 | E7: 4 | F7: =ROUND((D7+E7)/2,0) | G7: 1 | H7: =G7+F7-1 | I7: =$B$4+(G7-1)*7 | J7: =$B$4+H7*7-1 | K7: =$B$4+SUM($D$7:D7)*7-1 | L7: =$B$4+SUM($E$7:E7)*7-1 | M7: =SUMIFS('User Stories'!$H$5:$H$200,'User Stories'!$J$5:$J$200,A7,'User Stories'!$F$5:$F$200,"Must")&" - "&SUMIFS('User Stories'!$I$5:$I$200,'User Stories'!$J$5:$J$200,A7,'User Stories'!$F$5:$F$200,"Must") | N7: A clean checkout builds in Visual Studio; you pause the program on a breakpoint; CI runs on push.
A8: M1 | B8: Luna engine: walking skeleton | C8: 3-4 | D8: 5 | E8: 9 | F8: =ROUND((D8+E8)/2,0) | G8: =H7+1 | H8: =G8+F8-1 | I8: =$B$4+(G8-1)*7 | J8: =$B$4+H8*7-1 | K8: =$B$4+SUM($D$7:D8)*7-1 | L8: =$B$4+SUM($E$7:E8)*7-1 | M8: =SUMIFS('User Stories'!$H$5:$H$200,'User Stories'!$J$5:$J$200,A8,'User Stories'!$F$5:$F$200,"Must")&" - "&SUMIFS('User Stories'!$I$5:$I$200,'User Stories'!$J$5:$J$200,A8,'User Stories'!$F$5:$F$200,"Must") | N8: Luna opens a window; a demo character walks around a tile map at 60 FPS with crisp pixels at any window size; the build proves Luna contains no Odysseus code.
A9: M1b | B9: Luna Physics (deterministic 3D) | C9: 5 | D9: 6 | E9: 12 | F9: =ROUND((D9+E9)/2,0) | G9: =H8+1 | H9: =G9+F9-1 | I9: =$B$4+(G9-1)*7 | J9: =$B$4+H9*7-1 | K9: =$B$4+SUM($D$7:D9)*7-1 | L9: =$B$4+SUM($E$7:E9)*7-1 | M9: =SUMIFS('User Stories'!$H$5:$H$200,'User Stories'!$J$5:$J$200,A9,'User Stories'!$F$5:$F$200,"Must")&" - "&SUMIFS('User Stories'!$I$5:$I$200,'User Stories'!$J$5:$J$200,A9,'User Stories'!$F$5:$F$200,"Must") | N9: Luna Physics passes its math, hit-detection, ballistics and rigid-body tests identically on every build; in the demo the hero throws a spear that flies in an arc with a shadow and hits a target.
A10: M2 | B10: Console clan simulator (KILL GATE 1) | C10: 1-2 | D10: 8 | E10: 15 | F10: =ROUND((D10+E10)/2,0) | G10: =H9+1 | H10: =G10+F10-1 | I10: =$B$4+(G10-1)*7 | J10: =$B$4+H10*7-1 | K10: =$B$4+SUM($D$7:D10)*7-1 | L10: =$B$4+SUM($E$7:E10)*7-1 | M10: =SUMIFS('User Stories'!$H$5:$H$200,'User Stories'!$J$5:$J$200,A10,'User Stories'!$F$5:$F$200,"Must")&" - "&SUMIFS('User Stories'!$I$5:$I$200,'User Stories'!$J$5:$J$200,A10,'User Stories'!$F$5:$F$200,"Must") | N10: The headless runner simulates a 20-person clan for 100 years without crashing; the printed chronicle is shown to 3 people and at least 2 find a story in it; the determinism test passes.
A11: M2b | B11: Story engine (KILL GATE 1 retry) | C11: 1-2 | D11: 10 | E11: 20 | F11: =ROUND((D11+E11)/2,0) | G11: =H10+1 | H11: =G11+F11-1 | I11: =$B$4+(G11-1)*7 | J11: =$B$4+H11*7-1 | K11: =$B$4+SUM($D$7:D11)*7-1 | L11: =$B$4+SUM($E$7:E11)*7-1 | M11: =SUMIFS('User Stories'!$H$5:$H$200,'User Stories'!$J$5:$J$200,A11,'User Stories'!$F$5:$F$200,"Must")&" - "&SUMIFS('User Stories'!$I$5:$I$200,'User Stories'!$J$5:$J$200,A11,'User Stories'!$F$5:$F$200,"Must") | N11: The chronicle tells the clan's story in fewer, bigger episodes with reasons; every death and feud says why; the 100-year soak still runs without crashing and the determinism test passes; the owner reads the printed story and judges whether it is a story (Kill Gate 1 retry).
A12: M2c | B12: Level editor (Game mode and Editor mode) | C12: 1-2 | D12: 3 | E12: 8 | F12: =ROUND((D12+E12)/2,0) | G12: =H11+1 | H12: =G12+F12-1 | I12: =$B$4+(G12-1)*7 | J12: =$B$4+H12*7-1 | K12: =$B$4+SUM($D$7:D12)*7-1 | L12: =$B$4+SUM($E$7:E12)*7-1 | M12: =SUMIFS('User Stories'!$H$5:$H$200,'User Stories'!$J$5:$J$200,A12,'User Stories'!$F$5:$F$200,"Must")&" - "&SUMIFS('User Stories'!$I$5:$I$200,'User Stories'!$J$5:$J$200,A12,'User Stories'!$F$5:$F$200,"Must") | N12: The owner switches between Game mode and Editor mode, paints ground tiles, places characters with properties, sets the level's name, size, default ground and hero start, saves, reloads and plays the level; the demos still work.
A13: M2d | B13: Content and combat (weapons, nature, effects, weather) | C13: 46024 | D13: 4 | E13: 9 | F13: =ROUND((D13+E13)/2,0) | G13: =H12+1 | H13: =G13+F13-1 | I13: =$B$4+(G13-1)*7 | J13: =$B$4+H13*7-1 | K13: =$B$4+SUM($D$7:D13)*7-1 | L13: =$B$4+SUM($E$7:E13)*7-1 | M13: =SUMIFS('User Stories'!$H$5:$H$200,'User Stories'!$J$5:$J$200,A13,'User Stories'!$F$5:$F$200,"Must")&" - "&SUMIFS('User Stories'!$I$5:$I$200,'User Stories'!$J$5:$J$200,A13,'User Stories'!$F$5:$F$200,"Must") | N13: The hero fights with 16 starter weapons of 8 classes and elements; enemies strike back; plants block, are chopped and eaten and regrow; animals and effects are placed in the Editor; the weather changes by itself.
A14: M3 | B14: Living clan on screen | C14: 5-6 | D14: 3 | E14: 6 | F14: =ROUND((D14+E14)/2,0) | G14: =H13+1 | H14: =G14+F14-1 | I14: =$B$4+(G14-1)*7 | J14: =$B$4+H14*7-1 | K14: =$B$4+SUM($D$7:D14)*7-1 | L14: =$B$4+SUM($E$7:E14)*7-1 | M14: =SUMIFS('User Stories'!$H$5:$H$200,'User Stories'!$J$5:$J$200,A14,'User Stories'!$F$5:$F$200,"Must")&" - "&SUMIFS('User Stories'!$I$5:$I$200,'User Stories'!$J$5:$J$200,A14,'User Stories'!$F$5:$F$200,"Must") | N14: The clan from M2 and M2b runs inside the game; NPCs are visible, dressed in layered outfits, and act on their needs.
A15: M4 | B15: Region, tools and saves | C15: 7-9 | D15: 5 | E15: 10 | F15: =ROUND((D15+E15)/2,0) | G15: =H14+1 | H15: =G15+F15-1 | I15: =$B$4+(G15-1)*7 | J15: =$B$4+H15*7-1 | K15: =$B$4+SUM($D$7:D15)*7-1 | L15: =$B$4+SUM($E$7:E15)*7-1 | M15: =SUMIFS('User Stories'!$H$5:$H$200,'User Stories'!$J$5:$J$200,A15,'User Stories'!$F$5:$F$200,"Must")&" - "&SUMIFS('User Stories'!$I$5:$I$200,'User Stories'!$J$5:$J$200,A15,'User Stories'!$F$5:$F$200,"Must") | N15: A region is generated from a seed with biomes, resources and two rival clans; any NPC can be inspected; the game saves and loads.
A16: M5 | B16: Vertical slice feature-complete | C16: 10 | D16: 16 | E16: 31 | F16: =ROUND((D16+E16)/2,0) | G16: =H15+1 | H16: =G16+F16-1 | I16: =$B$4+(G16-1)*7 | J16: =$B$4+H16*7-1 | K16: =$B$4+SUM($D$7:D16)*7-1 | L16: =$B$4+SUM($E$7:E16)*7-1 | M16: =SUMIFS('User Stories'!$H$5:$H$200,'User Stories'!$J$5:$J$200,A16,'User Stories'!$F$5:$F$200,"Must")&" - "&SUMIFS('User Stories'!$I$5:$I$200,'User Stories'!$J$5:$J$200,A16,'User Stories'!$F$5:$F$200,"Must") | N16: A player can start a new game, live the Growing Period, take a profession, pursue Trade or Religion, and win or lose.
A17: M7 | B17: World interactions | C17: - | D17: 8 | E17: 16 | F17: =ROUND((D17+E17)/2,0) | G17: =H16+1 | H17: =G17+F17-1 | I17: =$B$4+(G17-1)*7 | J17: =$B$4+H17*7-1 | K17: =$B$4+SUM($D$7:D17)*7-1 | L17: =$B$4+SUM($E$7:E17)*7-1 | M17: =SUMIFS('User Stories'!$H$5:$H$200,'User Stories'!$J$5:$J$200,A17,'User Stories'!$F$5:$F$200,"Must")&" - "&SUMIFS('User Stories'!$I$5:$I$200,'User Stories'!$J$5:$J$200,A17,'User Stories'!$F$5:$F$200,"Must") | N17: Every action in today's game comes from data files; the player, NPCs and animals act on things with timed, visible, saved results; files edited offline reload with F5 and errors name file and line.
A18: M8 | B18: Speak to NPCs | C18: - | D18: 7 | E18: 14 | F18: =ROUND((D18+E18)/2,0) | G18: =H17+1 | H18: =G18+F18-1 | I18: =$B$4+(G18-1)*7 | J18: =$B$4+H18*7-1 | K18: =$B$4+SUM($D$7:D18)*7-1 | L18: =$B$4+SUM($E$7:E18)*7-1 | M18: =SUMIFS('User Stories'!$H$5:$H$200,'User Stories'!$J$5:$J$200,A18,'User Stories'!$F$5:$F$200,"Must")&" - "&SUMIFS('User Stories'!$I$5:$I$200,'User Stories'!$J$5:$J$200,A18,'User Stories'!$F$5:$F$200,"Must") | N18: The player talks to any clan member; written conversations branch on the simulation; without a script NPCs make small talk from their memories; talk changes opinions, items and memories; NPCs talk to each other in bubbles.
A19: M9 | B19: Interaction and dialogue editor | C19: - | D19: 8 | E19: 16 | F19: =ROUND((D19+E19)/2,0) | G19: =H18+1 | H19: =G19+F19-1 | I19: =$B$4+(G19-1)*7 | J19: =$B$4+H19*7-1 | K19: =$B$4+SUM($D$7:D19)*7-1 | L19: =$B$4+SUM($E$7:E19)*7-1 | M19: =SUMIFS('User Stories'!$H$5:$H$200,'User Stories'!$J$5:$J$200,A19,'User Stories'!$F$5:$F$200,"Must")&" - "&SUMIFS('User Stories'!$I$5:$I$200,'User Stories'!$J$5:$J$200,A19,'User Stories'!$F$5:$F$200,"Must") | N19: The owner opens any dialogue or interaction in the Editor as a graph, edits it, test-plays it and saves it, and the file still reads well in a text editor.
A20: M6 | B20: Playtest and go/no-go (KILL GATE 2) | C20: - | D20: 3 | E20: 4 | F20: =ROUND((D20+E20)/2,0) | G20: =H19+1 | H20: =G20+F20-1 | I20: =$B$4+(G20-1)*7 | J20: =$B$4+H20*7-1 | K20: =$B$4+SUM($D$7:D20)*7-1 | L20: =$B$4+SUM($E$7:E20)*7-1 | M20: =SUMIFS('User Stories'!$H$5:$H$200,'User Stories'!$J$5:$J$200,A20,'User Stories'!$F$5:$F$200,"Must")&" - "&SUMIFS('User Stories'!$I$5:$I$200,'User Stories'!$J$5:$J$200,A20,'User Stories'!$F$5:$F$200,"Must") | N20: 8 outside playtesters play; success criteria measured; go/no-go decision recorded. Held after M9 (owner, 2026-10-01, D-34).
B21: MVP total | D21: =SUM(D7:D20) | E21: =SUM(E7:E20) | F21: =SUM(F7:F20) | H21: =H20 | I21: =I7 | J21: =J20 | K21: =K20 | L21: =L20 | N21: Months (likely) = weeks / 4.33
B22: In months | D22: =ROUND(D21/4.33,1) | E22: =ROUND(E21/4.33,1) | F22: =ROUND(F21/4.33,1)
B24: Why the estimate grew: the learning path (requirements, section 8.3) estimated 9-13 months top-down. The bottom-up sum of the MVP stories is higher; this sheet uses the bottom-up figure.
B25: Buffer: the 'Should' stories are the cut list if time runs short. Cutting all of them saves about 5-11 weeks.
B26: Kill gates: M2 (is the console chronicle interesting? failed 2026-09-30, passed at the M2b retry) and M6 (do playtesters stay?), held after M9 (D-34). Critical path: M0 > M1 > M1b > M2 > M2b > M2c > M2d > M3 > M4 > M5 > M7 > M8 > M9 > M6. Dates of M2c onwards are not re-planned yet.

Sheet Dependencies
A1: Dependencies
A2: Design decisions you owe, external needs, and the technical chain. A story is Ready only when its dependencies are Decided.
A4: ID | B4: Dependency | C4: Type | D4: Needed by | E4: Blocks | F4: Owner | G4: Status
A5: D-01 | B5: Confirm time model: pausable real time with speed control (OPEN-04) | C5: Design decision | D5: M2 | E5: US-010 | F5: Owner | G5: Decided
A6: D-02 | B6: Side Characters: needs, traits, relationships (OPEN-10). Decided by Dominus (delegated), 2026-09-30. | C6: Design decision | D6: M2 (week 3) | E6: US-011, US-012, US-013 | F6: Owner + Dominus | G6: Decided
A7: D-03 | B7: Confirm the Age 1 needs set: Hunger, Energy, Warmth, Social | C7: Design decision | D7: M2 | E7: US-011 | F7: Owner | G7: Decided
A8: D-04 | B8: Sprite size and facing directions (OPEN-11). Owner answer 2026-09-29: 32x48 px, 8 directions. | C8: Design decision | D8: M1 | E8: US-022, US-024, US-030 | F8: Owner | G8: Decided
A9: D-05 | B9: Art source for placeholders: own, free asset pack, or hired (OPEN-12) | C9: Design decision | D9: M3 | E9: US-030 | F9: Owner | G9: Decided (2026-09-30): own art, placeholder quality; licence checked before a public release
A10: D-06 | B10: Minimum PC spec (OPEN-19) | C10: Design decision | D10: M4 | E10: US-082 | F10: Owner | G10: Open
A11: D-07 | B11: Calendar display (OPEN-15) | C11: Design decision | D11: M4 | E11: US-050, US-083 | F11: Owner | G11: Open
A12: D-08 | B12: Interactions interview: verbs, objects, crafting (OPEN-09) | C12: Design decision | D12: M4 | E12: US-061, US-062 | F12: Owner + Dominus | G12: Decided (answered by D-34)
A13: D-09 | B13: Confirm the five Age 1 professions (MVP-07) | C13: Design decision | D13: M4 | E13: US-060 | F13: Owner | G13: Proposed
A14: D-10 | B14: Confirm MVP pillars Trade + Religion (MVP-08) and victory thresholds (MVP-09) | C14: Design decision | D14: M5 | E14: US-070..US-073 | F14: Owner | G14: Proposed
A15: D-11 | B15: Story interview: tone of events, onboarding elder (OPEN-08) | C15: Design decision | D15: M5 | E15: US-052, US-090 | F15: Owner + Dominus | G15: Open
... A26: D-34 | B26: World interactions and dialogue (Round 13): plain-text .dlg dialogue + JSON interactions (comments allowed); hybrid talk (written trees reading the simulation + generated small talk); full visual graph editor plus F5 hot reload; build M7-M9 first, kill gate 2 after | C26: Design decision | D26: M7 | E26: US-150..US-175 | F26: Owner | G26: Decided

Sheet Epics
A1: Epics
A2: Counts, effort and progress are formulas over the User Stories sheet.
A4: ID | B4: Epic | C4: Outcome | D4: Milestone | E4: Stories | F4: Must | G4: Weeks (low) | H4: Weeks (high) | I4: Done | J4: Progress
A5: E0 | B5: Foundations | C5: Every change builds, is tested and is safe to make. | D5: M0 | E5: =COUNTIF('User Stories'!$B$5:$B$200,A5) | F5: =COUNTIFS('User Stories'!$B$5:$B$200,A5,'User Stories'!$F$5:$F$200,"Must") | G5: =SUMIF('User Stories'!$B$5:$B$200,A5,'User Stories'!$H$5:$H$200) | H5: =SUMIF('User Stories'!$B$5:$B$200,A5,'User Stories'!$I$5:$I$200) | I5: =COUNTIFS('User Stories'!$B$5:$B$200,A5,'User Stories'!$O$5:$O$200,"Done") | J5: =IFERROR(I5/E5,0)
A6: E1 | B6: Headless clan simulation | C6: A clan lives, remembers and produces a readable chronicle, with no graphics. | D6: M2 | E6: =COUNTIF('User Stories'!$B$5:$B$200,A6) | F6: =COUNTIFS('User Stories'!$B$5:$B$200,A6,'User Stories'!$F$5:$F$200,"Must") | G6: =SUMIF('User Stories'!$B$5:$B$200,A6,'User Stories'!$H$5:$H$200) | H6: =SUMIF('User Stories'!$B$5:$B$200,A6,'User Stories'!$I$5:$I$200) | I6: =COUNTIFS('User Stories'!$B$5:$B$200,A6,'User Stories'!$O$5:$O$200,"Done") | J6: =IFERROR(I6/E6,0)
A7: E2 | B7: Luna engine walking skeleton | C7: The player sees and controls a character in a window. | D7: M1 | E7: =COUNTIF('User Stories'!$B$5:$B$200,A7) | F7: =COUNTIFS('User Stories'!$B$5:$B$200,A7,'User Stories'!$F$5:$F$200,"Must") | G7: =SUMIF('User Stories'!$B$5:$B$200,A7,'User Stories'!$H$5:$H$200) | H7: =SUMIF('User Stories'!$B$5:$B$200,A7,'User Stories'!$I$5:$I$200) | I7: =COUNTIFS('User Stories'!$B$5:$B$200,A7,'User Stories'!$O$5:$O$200,"Done") | J7: =IFERROR(I7/E7,0)
A8: E3 | B8: Characters on screen | C8: The simulated clan is visible and readable at a glance. | D8: M3 | E8: =COUNTIF('User Stories'!$B$5:$B$200,A8) | F8: =COUNTIFS('User Stories'!$B$5:$B$200,A8,'User Stories'!$F$5:$F$200,"Must") | G8: =SUMIF('User Stories'!$B$5:$B$200,A8,'User Stories'!$H$5:$H$200) | H8: =SUMIF('User Stories'!$B$5:$B$200,A8,'User Stories'!$I$5:$I$200) | I8: =COUNTIFS('User Stories'!$B$5:$B$200,A8,'User Stories'!$O$5:$O$200,"Done") | J8: =IFERROR(I8/E8,0)
A9: E4 | B9: Procedural region | C9: Every new game has a different, believable region to live in. | D9: M4 | E9: =COUNTIF('User Stories'!$B$5:$B$200,A9) | F9: =COUNTIFS('User Stories'!$B$5:$B$200,A9,'User Stories'!$F$5:$F$200,"Must") | G9: =SUMIF('User Stories'!$B$5:$B$200,A9,'User Stories'!$H$5:$H$200) | H9: =SUMIF('User Stories'!$B$5:$B$200,A9,'User Stories'!$I$5:$I$200) | I9: =COUNTIFS('User Stories'!$B$5:$B$200,A9,'User Stories'!$O$5:$O$200,"Done") | J9: =IFERROR(I9/E9,0)
A10: E5 | B10: Life and the Growing Period | C10: The player's choices from 12 to 26 shape who the hero becomes. | D10: M5 | E10: =COUNTIF('User Stories'!$B$5:$B$200,A10) | F10: =COUNTIFS('User Stories'!$B$5:$B$200,A10,'User Stories'!$F$5:$F$200,"Must") | G10: =SUMIF('User Stories'!$B$5:$B$200,A10,'User Stories'!$H$5:$H$200) | H10: =SUMIF('User Stories'!$B$5:$B$200,A10,'User Stories'!$I$5:$I$200) | I10: =COUNTIFS('User Stories'!$B$5:$B$200,A10,'User Stories'!$O$5:$O$200,"Done") | J10: =IFERROR(I10/E10,0)
A11: E6 | B11: Professions and interactions | C11: The player works, crafts and learns a trade in the world. | D11: M5 | E11: =COUNTIF('User Stories'!$B$5:$B$200,A11) | F11: =COUNTIFS('User Stories'!$B$5:$B$200,A11,'User Stories'!$F$5:$F$200,"Must") | G11: =SUMIF('User Stories'!$B$5:$B$200,A11,'User Stories'!$H$5:$H$200) | H11: =SUMIF('User Stories'!$B$5:$B$200,A11,'User Stories'!$I$5:$I$200) | I11: =COUNTIFS('User Stories'!$B$5:$B$200,A11,'User Stories'!$O$5:$O$200,"Done") | J11: =IFERROR(I11/E11,0)
A12: E7 | B12: Pillars and regional dominion | C12: The player can lead the region through Trade or Religion. | D12: M5 | E12: =COUNTIF('User Stories'!$B$5:$B$200,A12) | F12: =COUNTIFS('User Stories'!$B$5:$B$200,A12,'User Stories'!$F$5:$F$200,"Must") | G12: =SUMIF('User Stories'!$B$5:$B$200,A12,'User Stories'!$H$5:$H$200) | H12: =SUMIF('User Stories'!$B$5:$B$200,A12,'User Stories'!$I$5:$I$200) | I12: =COUNTIFS('User Stories'!$B$5:$B$200,A12,'User Stories'!$O$5:$O$200,"Done") | J12: =IFERROR(I12/E12,0)
A13: E8 | B13: Saves, settings and quality | C13: The game is stable, fast, and never loses progress. | D13: M4-M5 | E13: =COUNTIF('User Stories'!$B$5:$B$200,A13) | F13: =COUNTIFS('User Stories'!$B$5:$B$200,A13,'User Stories'!$F$5:$F$200,"Must") | G13: =SUMIF('User Stories'!$B$5:$B$200,A13,'User Stories'!$H$5:$H$200) | H13: =SUMIF('User Stories'!$B$5:$B$200,A13,'User Stories'!$I$5:$I$200) | I13: =COUNTIFS('User Stories'!$B$5:$B$200,A13,'User Stories'!$O$5:$O$200,"Done") | J13: =IFERROR(I13/E13,0)
A14: E9 | B14: Playtest readiness | C14: Outside players can install, learn and play the slice. | D14: M6 | E14: =COUNTIF('User Stories'!$B$5:$B$200,A14) | F14: =COUNTIFS('User Stories'!$B$5:$B$200,A14,'User Stories'!$F$5:$F$200,"Must") | G14: =SUMIF('User Stories'!$B$5:$B$200,A14,'User Stories'!$H$5:$H$200) | H14: =SUMIF('User Stories'!$B$5:$B$200,A14,'User Stories'!$I$5:$I$200) | I14: =COUNTIFS('User Stories'!$B$5:$B$200,A14,'User Stories'!$O$5:$O$200,"Done") | J14: =IFERROR(I14/E14,0)
A15: E10 | B15: Luna physics | C15: Luna simulates hits, throws and bodies with deterministic 3D physics. | D15: M1b | E15: =COUNTIF('User Stories'!$B$5:$B$200,A15) | F15: =COUNTIFS('User Stories'!$B$5:$B$200,A15,'User Stories'!$F$5:$F$200,"Must") | G15: =SUMIF('User Stories'!$B$5:$B$200,A15,'User Stories'!$H$5:$H$200) | H15: =SUMIF('User Stories'!$B$5:$B$200,A15,'User Stories'!$I$5:$I$200) | I15: =COUNTIFS('User Stories'!$B$5:$B$200,A15,'User Stories'!$O$5:$O$200,"Done") | J15: =IFERROR(I15/E15,0)
A16: E11 | B16: Story engine | C16: The clan's life becomes a readable story: episodes with causes, people and consequences. | D16: M2b | E16: =COUNTIF('User Stories'!$B$5:$B$200,A16) | F16: =COUNTIFS('User Stories'!$B$5:$B$200,A16,'User Stories'!$F$5:$F$200,"Must") | G16: =SUMIF('User Stories'!$B$5:$B$200,A16,'User Stories'!$H$5:$H$200) | H16: =SUMIF('User Stories'!$B$5:$B$200,A16,'User Stories'!$I$5:$I$200) | I16: =COUNTIFS('User Stories'!$B$5:$B$200,A16,'User Stories'!$O$5:$O$200,"Done") | J16: =IFERROR(I16/E16,0)
... A21: E16 | B21: Interaction and dialogue editor | C21: The owner edits every conversation and interaction as a graph in the Editor, test-plays it and saves readable files. | D21: M9 | E21: =COUNTIF('User Stories'!$B$5:$B$200,A21) | F21: =COUNTIFS('User Stories'!$B$5:$B$200,A21,'User Stories'!$F$5:$F$200,"Must") | G21: =SUMIF('User Stories'!$B$5:$B$200,A21,'User Stories'!$H$5:$H$200) | H21: =SUMIF('User Stories'!$B$5:$B$200,A21,'User Stories'!$I$5:$I$200) | I21: =COUNTIFS('User Stories'!$B$5:$B$200,A21,'User Stories'!$O$5:$O$200,"Done") | J21: =IFERROR(I21/E21,0)
B22: Total | E22: =SUM(E5:E21) | F22: =SUM(F5:F21) | G22: =SUM(G5:G21) | H22: =SUM(H5:H21) | I22: =SUM(I5:I21) | J22: =IFERROR(I22/E22,0)

Sheet User Stories
A1: User stories with acceptance criteria
A2: Yellow Status column is yours. Weeks come from the size table on Read Me. Gherkin: Given (context), When (action), Then (observable result).
A4: ID | B4: Epic | C4: Title | D4: User story | E4: Acceptance criteria | F4: Priority | G4: Size | H4: Weeks (low) | I4: Weeks (high) | J4: Milestone | K4: Depends on | L4: Traces to | M4: C++ you will learn | N4: Notes | O4: Status
A5: US-001 | B5: E0 | C5: Build and debug from a clean checkout | D5: As a developer, I want to clone the repository and build every target with one CMake preset, so that I can start working in minutes and never fight the build. | E5: Scenario: Clean build Given a fresh clone and the installed toolchain When I run the windows-x64-debug preset and build Then odysseus.exe, odysseus_headless.exe and odysseus_tests.exe are produced with zero warnings Scenario: Debugging Given the Debug build When I set a breakpoint in main() and start debugging in Visual Studio Then execution pauses at the breakpoint and I can inspect variables Scenario: Missing dependency Given a library missing from vcpkg.json When I build Then CMake fails with a message naming the missing library | F5: Must | G5: S | H5: =VLOOKUP(G5,'Read Me'!$A$13:$C$15,2,FALSE) | I5: =VLOOKUP(G5,'Read Me'!$A$13:$C$15,3,FALSE) | J5: M0 | K5: D-12 | L5: ADR-001, ADR-012, TEC-04 | M5: What compiler, linker and build system each do; CMake presets | O5: Done
A6: US-002 | B6: E0 | C6: Run the build and tests on every push | D6: As a developer, I want GitHub Actions to build and test every push on a Windows runner, so that mistakes are caught automatically, even when I forget to run tests. | E6: Scenario: Green push Given a commit that builds and passes tests When I push to GitHub Then the CI run succeeds within 15 minutes Scenario: Broken test Given a commit with a failing test When I push Then the CI run fails and names the failing test | F6: Must | G6: S | H6: =VLOOKUP(G6,'Read Me'!$A$13:$C$15,2,FALSE) | I6: =VLOOKUP(G6,'Read Me'!$A$13:$C$15,3,FALSE) | J6: M0 | K6: US-001, D-12 | L6: ADR-014 | M6: Git basics: commit, branch, push | O6: Done
A7: US-003 | B7: E0 | C7: Enforce the layer rules in the build | D7: As a developer, I want the build to reject code that breaks the five-layer rule or pulls game code into Luna, so that the architecture cannot rot by accident. | E7: Scenario: Allowed use Given Game code that includes an Engine header When I build Then the build succeeds Scenario: Forbidden use Given Simulation code that includes an Engine or SDL3 header When I build Then the build fails with an include error Scenario: Luna stays game-agnostic Given Luna code that includes a Simulation or Game header When I build Then the build fails with an include error | F7: Must | G7: S | H7: =VLOOKUP(G7,'Read Me'!$A$13:$C$15,2,FALSE) | I7: =VLOOKUP(G7,'Read Me'!$A$13:$C$15,3,FALSE) | J7: M0 | K7: US-001 | L7: ARC-01, ARC-02, ARC-09, ADR-004 | M7: CMake targets and target_link_libraries | O7: Done
A8: US-004 | B8: E0 | C8: Log what happens and stop on broken assumptions | D8: As a developer, I want a logging system and asserts in Core, so that I can see what the game did before a problem. | E8: Scenario: Log file Given the game has run When I open the per-user logs folder Then a log file for the session exists with timestamped lines Scenario: Rotation Given six sessions have run When I open the logs folder Then only the last five session logs are kept Scenario: Assert Given a Debug build and an assert whose condition is false When that line runs Then the debugger stops there and the log records file and line | F8: Must | G8: S | H8: =VLOOKUP(G8,'Read Me'!$A$13:$C$15,2,FALSE) | I8: =VLOOKUP(G8,'Read Me'!$A$13:$C$15,3,FALSE) | J8: M0 | K8: US-001 | L8: Architecture 7.8 | M8: Header/source files, namespaces, macros | O8: Done
A9: US-010 | B9: E1 | C9: Advance a seeded world clock | D9: As a developer, I want the simulation to tick 20 times per second of game time with a calendar of days and seasons, so that everything in the world happens on one reliable clock. | E9: Scenario: Calendar Given a new simulation with seed 42 When it runs for one in-game year Then the calendar has passed through four seasons and the day counter matches the configured year length Scenario: Determinism Given two runs with seed 42 and the same inputs When each runs 10,000 ticks Then both produce the same world hash Scenario: Speed control Given the simulation at speed 4x When one real second passes Then 4 seconds of game time have advanced | F9: Must | G9: M | H9: =VLOOKUP(G9,'Read Me'!$A$13:$C$15,2,FALSE) | I9: =VLOOKUP(G9,'Read Me'!$A$13:$C$15,3,FALSE) | J9: M2 | K9: D-01 | L9: ADR-006, ADR-011, ARC-07, MVP-12 | M9: The game loop and accumulator; integers vs floats | O9: Done
A10: US-011 | B10: E1 | C10: Give every person needs that change over time | D10: As a player, I want clan members to get hungry, tired, cold and lonely, so that the world feels alive and people have reasons to act. | E10: Scenario: Decay Given a person with full needs When one in-game day passes without eating, sleeping, warmth or company Then each need has dropped by its configured daily rate Scenario: Satisfaction Given a hungry person When they eat a meal Then Hunger rises by the meal's value, capped at the maximum Scenario: Consequence Given a person whose Hunger stays at zero for the configured number of days When the next day starts Then they die and the chronicle records the cause | F10: Must | G10: M | H10: =VLOOKUP(G10,'Read Me'!$A$13:$C$15,2,FALSE) | I10: =VLOOKUP(G10,'Read Me'!$A$13:$C$15,3,FALSE) | J10: M2 | K10: D-02, D-03 | L10: SDC-01 (candidate), Overview v0.1 | M10: Plain structs as components; std::vector | N10: Needs set is an assumption until D-03 is confirmed. | O10: Done
A11: US-012 | B11: E1 | C11: Let people choose what to do (utility AI) | D11: As a player, I want each clan member to pick sensible actions based on their needs and skills, so that the clan survives without me micromanaging it. | E11: Scenario: Pick best action Given a person who is very hungry and slightly tired When the AI evaluates available actions Then a food action (gather or hunt) scores highest and is chosen Scenario: No option Given a person with no reachable action that satisfies a need When the AI evaluates Then they wander or rest instead of freezing, and no error occurs Scenario: Inspectable Given any person When I print their last decision in the headless runner Then I see every action's score and the chosen one | F11: Must | G11: L | H11: =VLOOKUP(G11,'Read Me'!$A$13:$C$15,2,FALSE) | I11: =VLOOKUP(G11,'Read Me'!$A$13:$C$15,3,FALSE) | J11: M2 | K11: US-011, D-02 | L11: SDC-01 (candidate utility AI) | M11: Functions as systems; enums; sorting | O11: Done
A12: US-013 | B12: E1 | C12: Remember events and spread gossip | D12: As a player, I want people to remember important events and tell others, so that reputations form and stories travel through the clan. | E12: Scenario: Memory Given a person who is given a gift When the event happens Then they store a memory with who, what, when and a feeling Scenario: Gossip Given two people who talk When one has a memory the other lacks Then the listener may gain a slightly weaker copy of that memory Scenario: Forgetting Given a minor memory older than its lifetime When the day ends Then it is forgotten; important memories are kept | F12: Must | G12: M | H12: =VLOOKUP(G12,'Read Me'!$A$13:$C$15,2,FALSE) | I12: =VLOOKUP(G12,'Read Me'!$A$13:$C$15,3,FALSE) | J12: M2 | K12: US-012, D-02 | L12: GD-03 (candidate), SDC-01 | M12: Containers of structs; references | O12: Done
A13: US-014 | B13: E1 | C13: Write a readable chronicle | D13: As a player, I want notable events recorded as short sentences, so that I can read the clan's story and share it. | E13: Scenario: Record Given a birth, death, first hunt of a mammoth or a feud When it happens Then the chronicle adds one sentence with the in-game date, e.g. 'Spring, year 3: Ura was born to Tok and Maa.' Scenario: Filter Given hundreds of minor events in a year When I print the chronicle for that year Then only events above the importance threshold appear | F13: Must | G13: M | H13: =VLOOKUP(G13,'Read Me'!$A$13:$C$15,2,FALSE) | I13: =VLOOKUP(G13,'Read Me'!$A$13:$C$15,3,FALSE) | J13: M2 | K13: US-013 | L13: NA-02 (candidate tapestry) | M13: std::string and formatting | O13: Done
A14: US-015 | B14: E1 | C14: Soak-test the simulation from the command line | D14: As a developer, I want to run the headless simulation for N years with a seed and get a report, so that I can check stability and balance in seconds. | E14: Scenario: Run Given the command odysseus_headless --seed 7 --years 100 When it runs Then it finishes without crashing and prints population, deaths by cause, average needs and tick time Scenario: Bad input Given --years -5 When I run it Then it prints a usage message and exits with an error code | F14: Must | G14: S | H14: =VLOOKUP(G14,'Read Me'!$A$13:$C$15,2,FALSE) | I14: =VLOOKUP(G14,'Read Me'!$A$13:$C$15,3,FALSE) | J14: M2 | K14: US-010..US-014 | L14: AQ-01, NFR-03, NFR-04 | M14: main(), command-line arguments | O14: Done
A15: US-016 | B15: E1 | C15: Save and load the simulation | D15: As a player, I want to save the world and load it later exactly as it was, so that I never lose my progress. | E15: Scenario: Round trip Given a simulation after 50 years When I save and load it Then the world hash after loading equals the hash before saving Scenario: Crash-safe Given a save interrupted halfway When I load Then the previous complete save loads and nothing crashes Scenario: Old version Given a save file from an earlier save version When I load it Then it is upgraded and loads, or a clear message explains why it cannot | F15: Must | G15: M | H15: =VLOOKUP(G15,'Read Me'!$A$13:$C$15,2,FALSE) | I15: =VLOOKUP(G15,'Read Me'!$A$13:$C$15,3,FALSE) | J15: M2 | K15: US-010, D-13 | L15: ADR-010, NFR-05 | M15: File I/O, JSON, error handling | O15: Done
A16: US-020 | B16: E2 | C16: Open a window with a steady game loop | D16: As a player, I want the game to open a window that runs smoothly and closes cleanly, so that the game feels solid from the first second. | E16: Scenario: Open Given the game is started When it launches Then a 1280 x 720 window opens within 3 seconds Scenario: Steady Given the loop is running When the frame time is measured for 60 seconds Then the average is 60 FPS on the development PC and simulation speed is identical at 30 and 144 Hz monitors Scenario: Close Given the window is open When I press the close button Then the game shuts down with no error in the log | F16: Must | G16: M | H16: =VLOOKUP(G16,'Read Me'!$A$13:$C$15,2,FALSE) | I16: =VLOOKUP(G16,'Read Me'!$A$13:$C$15,3,FALSE) | J16: M1 | K16: US-001, D-13 | L16: ADR-002, ADR-006, TEC-05 | M16: RAII wrapper around SDL_Window; unique_ptr with a custom deleter | O16: Done
A17: US-021 | B17: E2 | C17: Control the game through intents | D17: As a player, I want keyboard, mouse and gamepad to control the same actions, so that I can play the way I like, and touch can be added later. | E17: Scenario: Keyboard Given the default bindings When I press W Then the Move Up intent is produced Scenario: Gamepad Given a connected gamepad When I push the left stick up Then the same Move Up intent is produced Scenario: No raw keys Given the Game layer code When it is reviewed Then it only reads intents, never key codes | F17: Must | G17: S | H17: =VLOOKUP(G17,'Read Me'!$A$13:$C$15,2,FALSE) | I17: =VLOOKUP(G17,'Read Me'!$A$13:$C$15,3,FALSE) | J17: M1 | K17: US-020 | L17: ARC-03 | M17: Enums, mapping tables, std::unordered_map | O17: Done
A18: US-022 | B18: E2 | C18: Draw sprites with crisp pixels | D18: As a player, I want pixel art to stay sharp at every window size, so that the game looks right on any screen. | E18: Scenario: Integer scaling Given a 480 x 270 virtual screen When the window is resized to 1920 x 1080 Then the image scales by exactly 4 with no blurred pixels Scenario: Odd size Given a window size that is not an exact multiple When it is resized Then the image uses the largest whole-number scale and letterboxes the rest | F18: Must | G18: M | H18: =VLOOKUP(G18,'Read Me'!$A$13:$C$15,2,FALSE) | I18: =VLOOKUP(G18,'Read Me'!$A$13:$C$15,3,FALSE) | J18: M1 | K18: US-020, D-04 | L18: ENV-11, ADR-003 | M18: Interfaces with virtual functions (Renderer) | O18: Done
A19: US-023 | B19: E2 | C19: Show a tile map with a following camera | D19: As a player, I want to see the world around my character, with the camera following me, so that I always know where I am. | E19: Scenario: Draw Given a 64 x 64 test map When the game runs Then tiles within the camera view are drawn and tiles outside are skipped Scenario: Follow Given the character near the map centre When it moves Then the camera follows smoothly and stops at the map edges | F19: Must | G19: M | H19: =VLOOKUP(G19,'Read Me'!$A$13:$C$15,2,FALSE) | I19: =VLOOKUP(G19,'Read Me'!$A$13:$C$15,3,FALSE) | J19: M1 | K19: US-022 | L19: Architecture 7.4 | M19: 2D grids stored in a 1D vector | O19: Done
A20: US-024 | B20: E2 | C20: Walk the character around the map | D20: As a player, I want to move my character in four directions with animation, so that I feel in control of a person in the world. | E20: Scenario: Walk Given the character is idle When I hold Move Right Then it walks right with a walking animation at the configured speed Scenario: Blocked Given a rock tile to the right When I walk into it Then the character stops at the tile edge Scenario: Idle Given the character is walking When I release all movement input Then it stops and plays the idle animation facing the last direction | F20: Must | G20: M | H20: =VLOOKUP(G20,'Read Me'!$A$13:$C$15,2,FALSE) | I20: =VLOOKUP(G20,'Read Me'!$A$13:$C$15,3,FALSE) | J20: M1 | K20: US-021, US-023, D-04 | L20: ENV-11 | M20: State machines; simple collision | O20: Done
A21: US-030 | B21: E3 | C21: Compose characters from layers | D21: As a player, I want characters built from body, hair, outfit and held-item layers with colour variants, so that every person looks different and outfits can grow with progression. | E21: Scenario: Compose Given a body, a hair style, an outfit and a spear When the character is drawn Then all four layers line up in every animation frame and direction Scenario: Swap Given a character wearing outfit A When the outfit changes to B Then only the outfit layer changes Scenario: Palette Given one hair sprite When three palettes are applied Then three distinct hair colours appear without new art | F21: Must | G21: M | H21: =VLOOKUP(G21,'Read Me'!$A$13:$C$15,2,FALSE) | I21: =VLOOKUP(G21,'Read Me'!$A$13:$C$15,3,FALSE) | J21: M3 | K21: US-024, D-04, D-05 | L21: ENV-12, MVP-11 | M21: Composition over inheritance | O21: Done
A22: US-031 | B22: E3 | C22: Read people's state at a glance | D22: As a player, I want to see how people feel from their posture and small emote icons, so that I understand the clan without opening menus. | E22: Scenario: Emote Given a person whose Warmth is critical When they are on screen Then a shiver animation or cold emote is visible Scenario: Details on demand Given any person When I hover or click them Then a panel shows exact need values and current action | F22: Should | G22: S | H22: =VLOOKUP(G22,'Read Me'!$A$13:$C$15,2,FALSE) | I22: =VLOOKUP(G22,'Read Me'!$A$13:$C$15,3,FALSE) | J22: M3 | K22: US-032, US-011 | L22: UX-01 (candidate) | M22: Mapping data to presentation | O22: Done
... A53: US-029 | B53: E10 | C53: Throw a spear in the demo | D53: As a player, I want to throw a spear at a target in the walking skeleton, so that Luna Physics is proven end to end in the real game. | E53: Scenario: Throw Given the hero facing a straw target 8 tiles away When I press Interact Then a spear flies in a visible arc with a shadow and hits the target Scenario: Material Given a flint-tipped and a wooden spear (materials.json) When each hits the target Then the damage differs by the materials' hardness and density as configured Scenario: Blocked Given a target behind a rock When I throw at it Then the spear hits the rock and stops; the target is unharmed | F53: Must | G53: M | H53: =VLOOKUP(G53,'Read Me'!$A$13:$C$15,2,FALSE) | I53: =VLOOKUP(G53,'Read Me'!$A$13:$C$15,3,FALSE) | J53: M1b | K53: US-024, US-027, US-028 | L53: PHY-02, PHY-03, PHY-05 | M53: Putting it together; content as data (materials.json) | O53: Done
A54: US-110 | B54: E11 | C54: Give every death and feud a reason | D54: As a reader, I want every death and feud in the chronicle to say why it happened, so that events connect into a story. | E54: Scenario: Death with a cause Given a person who starves after the food store was robbed or ran empty When the death is recorded Then the sentence names the cause and the event behind it, e.g. 'Winter, year 74: Hano died of hunger in the hard winter, after Brak stole from the store.' Scenario: Feud with a reason Given two people whose opinions fell through thefts, quarrels or blame When their feud begins Then the sentence names what turned them, e.g. 'A feud broke out between Tok and Brak over stolen meat.' Scenario: Traceable Given any death or feud in the chronicle When I inspect it in the headless runner Then it lists the earlier events that caused it | F54: Must | G54: M | H54: =VLOOKUP(G54,'Read Me'!$A$13:$C$15,2,FALSE) | I54: =VLOOKUP(G54,'Read Me'!$A$13:$C$15,3,FALSE) | J54: M2b | K54: US-014 | L54: STO-03, NA-02 | M54: Small structs that point to other data (event ids); enums | N54: Kill Gate 1 pivot (owner, 2026-09-30, D-18) | O54: Done
A55: US-111 | B55: E11 | C55: Quarrel, blame and take revenge | D55: As a player, I want people to quarrel, blame each other for losses and seek revenge, so that conflicts have causes and consequences. | E55: Scenario: Quarrel Given two tired or hungry people who dislike each other When they meet Then they may quarrel; both remember it and think less of each other Scenario: Blame Given a person whose close kin died after a theft they know of, or on a hunt someone led When they grieve Then they blame the person linked to the cause and remember it for life Scenario: Revenge Given a feud that keeps worsening When revenge is taken Then it ends in a fight (injury or death) or the clan exiles the aggressor, and the chronicle tells which and why | F55: Must | G55: L | H55: =VLOOKUP(G55,'Read Me'!$A$13:$C$15,2,FALSE) | I55: =VLOOKUP(G55,'Read Me'!$A$13:$C$15,3,FALSE) | J55: M2b | K55: US-110 | L55: SDC-02, GD-03 | M55: State machines with enums; std::optional | N55: Kill Gate 1 pivot (owner, 2026-09-30, D-18) | O55: Done
A56: US-112 | B56: E11 | C56: Share food and nurse the sick | D56: As a player, I want people to share food in hard times and care for the sick and injured, so that kindness has weight and debts of gratitude form. | E56: Scenario: Sickness Given a person weakened by cold, hunger or a hunting wound When sickness or injury strikes Then they are sick or injured for some days and may die of it Scenario: Nursing Given a sick person and a kind or close person nearby When they are nursed Then recovery is likelier and the patient remembers the carer with gratitude Scenario: Sharing and adoption Given a hungry child or an orphan When a relative or friend has food or room Then they share or adopt, and the one helped remembers it | F56: Must | G56: L | H56: =VLOOKUP(G56,'Read Me'!$A$13:$C$15,2,FALSE) | I56: =VLOOKUP(G56,'Read Me'!$A$13:$C$15,3,FALSE) | J56: M2b | K56: US-110 | L56: SDC-02 | M56: Standard algorithms: std::find_if, std::max_element, std::sort | N56: Kill Gate 1 pivot (owner, 2026-09-30, D-18) | O56: Done
A57: US-113 | B57: E11 | C57: Court and compete for a partner | D57: As a player, I want courtship with rivals and broken pairings, so that love brings drama as well as children. | E57: Scenario: Courtship Given an unpaired adult who favours another When they court (gifts, time together) Then the other's opinion rises, and they pair only when both agree Scenario: Rivals Given two suitors courting the same person When one is chosen Then the rivals become jealous and may quarrel, and the one not chosen remembers it Scenario: Parting Given partners whose opinions of each other fall below the parting threshold When a day ends Then they part, and the chronicle records why | F57: Must | G57: M | H57: =VLOOKUP(G57,'Read Me'!$A$13:$C$15,2,FALSE) | I57: =VLOOKUP(G57,'Read Me'!$A$13:$C$15,3,FALSE) | J57: M2b | K57: US-111 | L57: SDC-02 | M57: Comparators and ranking (std::sort with a lambda) | N57: Kill Gate 1 pivot (owner, 2026-09-30, D-18) | O57: Done
A58: US-114 | B58: E11 | C58: Teach the young and hunt together | D58: As a player, I want masters to teach apprentices and hunters to go out in parties, so that skills pass down and hunts create heroes and cowards. | E58: Scenario: Apprenticeship Given a skilled adult and a youth of working age When the adult takes the youth as apprentice Then the youth's skill grows faster and they grow close Scenario: Hunting party Given a mammoth sighting When a party of 3 to 5 hunters forms and hunts Then roles emerge (leader, hero, coward), the outcome depends on the party, and each member remembers what the others did Scenario: Rescue Given a hunter in danger When another hunter saves them Then the rescued owes a debt of gratitude and the chronicle tells of it | F58: Must | G58: L | H58: =VLOOKUP(G58,'Read Me'!$A$13:$C$15,2,FALSE) | I58: =VLOOKUP(G58,'Read Me'!$A$13:$C$15,3,FALSE) | J58: M2b | K58: US-111 | L58: SDC-02 | M58: A class that coordinates others (the hunting party) | N58: Kill Gate 1 pivot (owner, 2026-09-30, D-18) | O58: Done
A59: US-115 | B59: E11 | C59: Tell the clan's story in episodes | D59: As a reader, I want the chronicle to tell fewer, bigger episodes with a beginning, a turn and an end, so that I can follow the clan's story. | E59: Scenario: Episode Given linked events (a lean autumn, thefts, blame, a feud, deaths) When the episode ends Then the chronicle writes it as one short named paragraph ('The Hard Winter of year 74') saying who, why and what came of it Scenario: Fewer, bigger Given a 100-year run When I print the story Then it tells at most 40 episodes, each naming its people and causes, followed by the births, deaths, pairings and feuds with their reasons Scenario: Both views Given the headless runner When I ask for the story or for the full chronicle Then --story prints the episodes and --chronicle still prints every event | F59: Must | G59: L | H59: =VLOOKUP(G59,'Read Me'!$A$13:$C$15,2,FALSE) | I59: =VLOOKUP(G59,'Read Me'!$A$13:$C$15,3,FALSE) | J59: M2b | K59: US-110, US-111, US-112, US-113, US-114 | L59: STO-02, STO-03, NA-02 | M59: Designing with data: grouping and summarising | N59: Kill Gate 1 pivot (owner, 2026-09-30, D-18) | O59: Done
A60: US-120 | B60: E12 | C60: Real art in the game | D60: As a player, I want the heroes, monsters and ground drawn from the new art, so that the world looks like the game I imagine. | E60: Scenario: Atlas Given the owner's sprite sheets in assets/sprites When the cutter tool runs Then it writes clean atlases (transparent background, 32x48 characters, 32x32 tiles) from rectangles kept in JSON Scenario: Heroes and ground Given the game starts When the hero walks the test map Then the hero, the ground tiles and the enemy are drawn from the atlases Scenario: Missing art Given an atlas file that is missing or damaged When the game starts Then it names the file and falls back to programmer art | F60: Must | G60: L | H60: 2 | I60: 4 | J60: M2c | K60: - | L60: D-05, D-19 | M60: Reading binary files; structs of rectangles | N60: Level editor (owner, 2026-09-30, D-19) | O60: Done
A61: US-121 | B61: E12 | C61: Point, click and read on screen | D61: As a level designer, I want to point, click and read labels on screen, so that I can use editor tools. | E61: Scenario: Pointer Given the mouse moves, clicks or scrolls When the events arrive Then the game reads a pointer (position, buttons, wheel), never raw SDL3 events Scenario: Text Given any label in printable ASCII When it is drawn Then it is readable and pixel-exact at 480x270 Scenario: Widgets Given a panel with buttons, a list and a number field When they are clicked or typed into Then the right action runs (tested headless) | F61: Must | G61: M | H61: 1 | I61: 2 | J61: M2c | K61: - | L61: D-19, ARC-03 | M61: Classes with virtual functions (widgets) | N61: Level editor (owner, 2026-09-30, D-19) | O61: Done
A62: US-122 | B62: E12 | C62: Levels as data | D62: As a level designer, I want levels saved as files, so that what I build stays and can be shared. | E62: Scenario: Load Given a level file When the game starts Then the map, ground, characters and hero start come from the file Scenario: Round trip Given a level When it is saved and loaded Then it is exactly the same Scenario: Damaged Given a damaged level file When it is loaded Then the error names the file and the field, and the last good backup is used | F62: Must | G62: M | H62: 1 | I62: 2 | J62: M2c | K62: US-120 | L62: D-19, ARC-08 | M62: Reading and writing JSON with validation | N62: Level editor (owner, 2026-09-30, D-19) | O62: Done
A63: US-123 | B63: E12 | C63: Game mode and Editor mode | D63: As a level designer, I want to switch between playing and editing, so that I can try what I build at once. | E63: Scenario: Switch Given the game running When I press F2 Then Editor mode is shown, the world pauses and the camera pans freely Scenario: Back to play Given the Editor with changes When I press F1 Then the game plays the edited level from the hero start Scenario: Game untouched Given Game mode When I play Then the spear and sword demos behave as before | F63: Must | G63: S | H63: 0.5 | I63: 1 | J63: M2c | K63: US-121, US-122 | L63: D-19 | M63: State machines (enum class) | N63: Level editor (owner, 2026-09-30, D-19) | O63: Done
A64: US-124 | B64: E12 | C64: Paint ground tiles | D64: As a level designer, I want to paint ground tiles by hand, so that I shape the world. | E64: Scenario: Paint Given a tile chosen in the palette When I click or drag on the map Then the cells change; solid tiles block walking in Game mode Scenario: Fill Given an area When I use the rectangle or flood fill Then the whole area is painted in one step Scenario: Undo Given a series of edits When I press Ctrl+Z or Ctrl+Y Then the level steps back and forward exactly | F64: Must | G64: M | H64: 1 | I64: 2 | J64: M2c | K64: US-123 | L64: D-19 | M64: The command pattern (undo and redo) | N64: Level editor (owner, 2026-09-30, D-19) | O64: Done
A65: US-125 | B65: E12 | C65: Place characters | D65: As a level designer, I want to place heroes and monsters in the world, so that the game has someone to meet. | E65: Scenario: Place Given a character chosen in the palette When I click on the map Then it appears there, facing south, with default properties Scenario: Edit Given a placed character When I select, move, turn or delete it, or change its name, HP or sword damage Then the change is shown and saved Scenario: Play Given a placed enemy When I hit it with the sword in Game mode Then it takes damage, flashes red and is defeated at 0 HP | F65: Must | G65: M | H65: 1 | I65: 2 | J65: M2c | K65: US-123, US-124 | L65: D-19 | M65: Owning objects in a std::vector; ids instead of pointers | N65: Level editor (owner, 2026-09-30, D-19) | O65: Done
A66: US-126 | B66: E12 | C66: Level and character settings | D66: As a level designer, I want to set the level's name, size, default ground and the hero's start, so that each level is my own. | E66: Scenario: Settings Given a level When I change its name, size or default ground Then it is saved and reloaded; a resize keeps the painted tiles Scenario: Hero start Given the hero start marker When I move it Then Game mode starts the hero there Scenario: Guide Given the owner When he opens docs/guides/editor.md Then every control is explained in plain words | F66: Must | G66: S | H66: 0.5 | I66: 1 | J66: M2c | K66: US-125 | L66: D-19 | M66: Resizing a 2D grid stored in one vector | N66: Level editor (owner, 2026-09-30, D-19) | O66: Done
A67: US-130 | B67: E13 | C67: Content catalogs from the new sheets | D67: As the owner, I want my seven new sprite sheets cut into game atlases and catalogs, so that weapons, plants, animals, effects and weather can be used in the game. | E67: Scenario: Cut Given the seven sheets and cuts.json When the atlas tool runs Then atlases and JSON catalogs exist for weapons, plants, animals, effects and weather, backgrounds removed Scenario: Review Given the owner When the owner opens the numbered contact sheets Then every item is shown with its catalog name | F67: Must | G67: L | H67: 2 | I67: 4 | J67: M2d | K67: US-120 | L67: D-05, D-21, ARC-08 | M67: Reading data tables with std::map and validating them | N67: Content and combat (owner, 2026-09-30, D-21) | O67: Done
A68: US-131 | B68: E13 | C68: Hero HP, fighting back and death | D68: As the player, I want enemies to strike back when I hit them, so that fighting has risk. | E68: Scenario: Strike back Given an enemy the hero hits while standing within 1.5 m When 0.5 s pass with a warning flash Then the hero loses the enemy kind's damage Scenario: Death Given the hero or an enemy at 0 HP When it happens Then the hero respawns at the start with 100 HP; the enemy dies and is gone until the level restarts | F68: Must | G68: M | H68: 1 | I68: 2 | J68: M2d | K68: US-125 | L68: D-21 | M68: A small state machine with enum class | N68: Content and combat (owner, 2026-09-30, D-21) | O68: Done
A69: US-132 | B69: E13 | C69: Effect player | D69: As the player, I want hits, deaths and projectiles to show effects, so that combat reads clearly. | E69: Scenario: One-shot Given an effect started in the world When its frames have played Then it disappears Scenario: Combat Given a sword hit, a death or an arrow in flight When it happens Then a hit spark, a smoke puff or a trail plays | F69: Must | G69: M | H69: 1 | I69: 2 | J69: M2d | K69: US-130 | L69: D-21, ARC-09 | M69: Timers and animation frames in a fixed timestep | N69: Content and combat (owner, 2026-09-30, D-21) | O69: Done
A70: US-133 | B70: E13 | C70: Weapon classes and the starter set | D70: As the player, I want each kind of weapon to fight differently, so that choosing a weapon matters. | E70: Scenario: Classes Given each of the 8 classes When the hero attacks Then its own attack shape, speed and range are used from JSON Scenario: In hand Given a weapon selected When the hero walks Then the weapon icon is drawn in the hero's hand | F70: Must | G70: L | H70: 2 | I70: 4 | J70: M2d | K70: US-130, US-132 | L70: D-21 | M70: Virtual functions or std::variant for weapon classes | N70: Content and combat (owner, 2026-09-30, D-21) | O70: Done
A71: US-134 | B71: E13 | C71: Pickups and the hotbar | D71: As a level designer, I want to place weapons in my levels for the hero to find, so that levels have rewards. | E71: Scenario: Pick up Given the hero walks over a pickup When it happens Then the weapon goes into the first free of 9 hotbar slots Scenario: Select Given weapons in the hotbar When I press 1-9 or Shift Then that weapon, or the next one, is held | F71: Must | G71: M | H71: 1 | I71: 2 | J71: M2d | K71: US-133 | L71: D-21, ADR-010 | M71: Upgrading a saved file format (version 1 to 2) | N71: Content and combat (owner, 2026-09-30, D-21) | O71: Done
...

Sheet Cut List
A1: Out of the MVP (and when it returns)
A2: Saying no, with reasons. Nothing here is lost: each item returns on the roadmap.
A4: Item | B4: Why it is cut from the MVP | C4: Returns
A5: Android and iOS builds | B5: No hypothesis depends on them; architecture already protects portability. | C5: After MVP (learning stage 11)
A6: Ages 2-10, Mythic Strands, Phase 2 space | B6: Each is a content project; the MVP must first prove Age 1 is fun. | C6: Post-MVP roadmap
A7: Whole planet, prehistory world-gen, LOD tiers Remote and Planet | B7: A region is enough to test the loop; planet scale is a performance project of its own. | C7: Next
A8: Military, Politics, Technology, Ideology pillars | B8: Two pillars are enough to test 'many paths to dominance'; combat is the most expensive system. | C8: Next (Politics), Later (others)
A9: Dynasty, Reincarnation, Rotating Avatar modes | B9: One mode tests the loop; the Succession system is built so others are configuration later. | C9: Next (Dynasty)
A10: Character Creator, Origin/Tribe, Legend modifiers | B10: Unlocks need progression that the MVP does not have yet. | C10: Next
A11: Ideology Forge, custom titles | B11: Depend on cut pillars. | C11: Later
A12: Real art pipeline, music | B12: Placeholder art is enough to test fun; art is expensive to redo. | C12: After the fun is proven
A13: Steam integration, achievements, cloud saves | B13: Distribution is not the MVP question (OPEN-18). | C13: Launch
A14: Advanced physics and chemistry (explosions, vehicles, orbits, heat, fire spread, reactions) | B14: Age 1 needs hit detection, ballistics, basic bodies and material properties only; the rest belongs to later Ages. | C14: With the Age that needs it (PHY-05, PHY-06)

Sheet Ready & Done
A1: Definition of Ready and Definition of Done
A2: Apply to every story.
A4: Definition of Ready: a story may start when...
A5: The story traces to an MVP scope item or a requirement.
